Workbook

Sheet Test Cases
A1: Module | B1: Transfer Banking
A2: Test requirement | B2: Verify the functionality and security of the Fund Transfer via Phone Number feature.
A3: Reference Document | B3: No official internal spec was available. Test cases were designed via self-exploratory testing of the live MoMo app (black-box), based on observed behavior and general fintech/e-wallet domain knowledge.
A4: No. Testcase | B4: 59
A5: TEST CASES – Money Transfer Feature | MoMo App
A6: Domain: Mobile Banking / Fintech | Module: Money Transfer | Tester: Nguyễn Ngọc Thanh Trúc
A7: Test Case ID | B7: Feature | C7: Test Scenario ID | D7: Test Case Title | E7: Preconditions | F7: Test Steps | G7: Test Data | H7: Expected Result | I7: Actual Result | J7: Status | K7: Severity | L7: Priority | M7: Type | N7: Notes | O7: Execution Method | P7: Jira Ref
A8: TC_001 | B8: Phone Number Input | C8: TS_TF_001 | D8: Successful transfer to a valid registered MoMo phone number | E8: 1. Successfully logged in to MoMo 2. Wallet has sufficient balance (≥ 10,000đ) 3. Recipient has a MoMo account | F8: 1. Open MoMo app 2. Select "Transfer Money" 3. Enter a valid recipient phone number 4. Enter a valid amount 5. Enter a message (optional) 6. Tap "Continue" 7. Confirm PIN | G8: Phone: 0901234567 Amount: 50,000đ Message: "cafe nha" | H8: Success screen is displayed. Wallet balance decreases by exactly 50,000đ. Transaction history is updated. | J8: NT | K8: Medium | L8: High | M8: Positive | N8: Happy Path
A9: TC_002 | B9: Phone Number Input | C9: TS_TF_002 | D9: Transfer to a phone number not registered with MoMo | E9: 1. Successfully logged in to MoMo 2. Wallet has sufficient balance | F9: 1. Select "Transfer Money" 2. Enter a phone number not registered with MoMo 3. Tap "Continue" | G9: Phone: 0999999999 (no MoMo account) | H9: Error message displayed: "This phone number has no registered account". Cannot proceed. | J9: NT | K9: Medium | L9: High | M9: Negative
A10: TC_003 | B10: Phone Number Input | C10: TS_TF_003 | D10: Transfer to your own phone number | E10: 1. Successfully logged in to MoMo | F10: 1. Select "Transfer Money" 2. Enter a phone number matching the logged-in account 3. Tap "Continue" | G10: Phone: the phone number of the current account | H10: Warning displayed: "Recipient account must be different from sender account". Cannot proceed. | J10: NT | K10: High | L10: High | M10: Negative
A11: TC_004 | B11: Phone Number Input | C11: TS_TF_004 | D11: Enter phone number in wrong format – fewer than 10 digits | E11: 1. Successfully logged in to MoMo | F11: 1. Select "Transfer Money" 2. Enter a phone number with only 9 digits 3. Observe the screen | G11: Phone: 090123456 (9 digits) | H11: Inline error displayed: "Invalid or non-existent phone number". Cannot proceed. | J11: NT | K11: Low | L11: Medium | M11: Negative
A12: TC_005 | B12: Phone Number Input | C12: TS_TF_005 | D12: Enter phone number in wrong format – more than 10 digits | E12: 1. Successfully logged in to MoMo | F12: 1. Select "Transfer Money" 2. Enter a phone number with 11 digits 3. Observe the screen | G12: Phone: 09012345622 (11 digits) | H12: Inline error displayed: "Invalid or non-existent phone number". Cannot proceed. | J12: NT | K12: Low | L12: Medium | M12: Negative
A13: TC_006 | B13: Phone Number Input | C13: TS_TF_006 | D13: Enter phone number containing special characters / letters | E13: 1. Successfully logged in to MoMo | F13: 1. Select "Transfer Money" 2. Try entering letters or special characters in the phone field 3. Observe the screen | G13: Input: "abc!@#" or "090abc123" | H13: Inline error displayed: "Invalid or non-existent phone number". Cannot proceed. | J13: NT | K13: Low | L13: Medium | M13: Negative
A14: TC_007 | B14: Phone Number Input | C14: TS_TF_007 | D14: Leave the phone number field empty and tap Continue | E14: 1. Successfully logged in to MoMo | F14: 1. Select "Transfer Money" 2. Leave the phone field empty 3. Tap "Continue" | G14: Phone: (empty) | H14: The "Continue" button is disabled when the phone field is empty. No screen transition occurs. | J14: NT | K14: Medium | L14: High | M14: Negative
A15: TC_008 | B15: Phone Number Input | C15: TS_TF_008 | D15: Phone number has leading/trailing spaces or is pasted from clipboard with unusual characters | E15: 1. Successfully logged in to MoMo | F15: 1. Select "Transfer Money" 2. Tap the phone field, then tap "Paste" 3. Tap "Continue" | G15: Phone: " 0901234567@" (pasted from clipboard, contains spaces and the "@" character) | H15: The system automatically trims extra spaces on paste. Invalid characters ("@") are blocked from input or trigger the error "Invalid phone number". Cannot proceed with a phone number containing unusual characters. The "Continue" button is not displayed. | J15: NT | K15: Medium | L15: Medium | M15: Negative
A16: TC_009 | B16: Phone Number Input | C16: TS_TF_009 | D16: Select recipient from contacts / "recent recipients" - verify auto-fill works correctly | E16: 1. Successfully logged in to MoMo | F16: 1. Select "Transfer Money" 2. Choose from "Select recipient from contacts" / "recent recipients" 3. Tap "Continue" | G16: Name: Nguyễn Thị Hà - 0903827456 | H16: The system correctly auto-fills the selected recipient's name and phone number into the transfer screen. The "Continue" button is displayed (enabled), allowing the transaction to proceed normally. | J16: NT | K16: Medium | L16: Medium | M16: Positive
A17: TC_010 | B17: Phone Number Input | C17: TS_TF_010 | D17: Select recipient from contacts / "recent recipients" but the account is locked/restricted - verify auto-fill behaves correctly | E17: 1. Successfully logged in to MoMo | F17: 1. Select "Transfer Money" 2. Choose from "Select recipient from contacts" / "recent recipients" whose account is locked/restricted 3. Tap "Continue" | G17: Phone: "locked phone number" | H17: Warning displayed: "Recipient account is locked/restricted". Cannot proceed with the transaction. | J17: NT | K17: Medium | L17: Medium | M17: Negative
A18: TC_011 | B18: Phone Number Input | C18: TS_TF_011 | D18: Recipient exists but the account is locked/restricted (different from TC_002, which is unregistered) | E18: 1. Successfully logged in to MoMo | F18: 1. Select "Transfer Money" 2. Enter a locked phone number 3. Tap "Continue" | G18: Phone: "locked phone number" | H18: Warning displayed: "Recipient account is locked/restricted". Cannot proceed with the transaction. | J18: NT | K18: Medium | L18: High | M18: Negative
A19: TC_012 | B19: Phone Number Input | C19: TS_TF_012 | D19: Phone prefix does not exist in Vietnam (e.g., 090 but the remaining digits don't match any carrier logic) or the SIM is two-way blocked | E19: 1. Successfully logged in to MoMo | F19: 1. Select "Transfer Money" 2. Choose a phone number that doesn't exist in Vietnam 3. Tap "Continue" | G19: Phone: 090125678 | H19: Inline error displayed: "Invalid or non-existent phone number". | J19: NT | K19: Low | L19: Medium | M19: Negative
A20: TC_013 | B20: Amount Input | C20: TS_AM_001 | D20: Enter a valid amount within the allowed limit | E20: 1. Successfully logged in 2. A valid recipient has been selected 3. Wallet balance ≥ transfer amount | F20: 1. Enter a valid recipient phone number 2. Enter an amount within the allowed range 3. Tap "Continue" | G20: Amount: 100,000đ (within [10,000 – 50,000,000]) | H20: Proceeds to the transaction confirmation screen with correct information. | J20: NT | K20: Medium | L20: High | M20: Positive
... A39: TC_032 | B39: Account Limit | C39: TS_KYC_005 | D39: A KYC-verified account transfers an amount that exceeds the non-KYC limit but is still within the KYC limit | E39: 1. Logged in with a non-KYC account 2. Wallet has sufficient balance | F39: 1. Enter an amount between the two limit thresholds 2. Tap "Continue" | G39: Amount: 30,000,000đ (assuming: > non-KYC limit of 10M, but < KYC limit of 50M) | H39: Transaction successful as normal. Not blocked. | J39: NT | K39: High | L39: High | M39: Positive
A40: TC_033 | B40: Account Limit | C40: TS_KYC_006 | D40: A non-KYC account is completely blocked from the transfer feature (if policy requires mandatory KYC) | E40: 1. Logged in with a non-KYC account | F40: 1. Go to the main screen 2. Select "Transfer Money" | G40: Action: tap the Transfer Money icon | H40: The system blocks access to the feature and displays a popup requiring KYC verification before use. | J40: NT | K40: Critical | L40: High | M40: Negative | N40: Needs BA confirmation: does the policy fully block, or only limit the amount?
A41: TC_034 | B41: PIN Confirmation | C41: TS_AU_001 | D41: Confirm transaction successfully with the correct PIN | E41: 1. Valid transfer information has been fully entered 2. Current PIN is known | F41: 1. Complete entering transfer information 2. Tap "Continue" 3. Enter the correct 6-digit PIN | G41: PIN: correct | H41: Transaction confirmed. Proceeds to the success result screen. | J41: NT | K41: High | L41: High | M41: Positive
A42: TC_035 | B42: PIN Confirmation | C42: TS_AU_002 | D42: Enter wrong PIN once, then enter the correct PIN | E42: 1. Transfer information has been fully entered | F42: 1. On the PIN entry screen 2. Enter the wrong PIN 3. Observe the error message 4. Re-enter the correct PIN | G42: Attempt 1: wrong PIN Attempt 2: correct PIN | H42: Attempt 1: Wrong-PIN message displayed, remaining attempts decrease. Attempt 2: Transaction successful. | J42: NT | K42: Medium | L42: High | M42: Negative
A43: TC_036 | B43: PIN Confirmation | C43: TS_AU_003 | D43: Enter the wrong PIN 5 times in a row → account gets locked | E43: 1. Transfer information has been fully entered | F43: 1. On the PIN entry screen 2. Enter the wrong PIN 5 times in a row | G43: PIN: wrong × 5 times | H43: After the 5th attempt: Account is temporarily locked. A message and unlock instructions are displayed. | J43: NT | K43: Critical | L43: High | M43: Security
A44: TC_037 | B44: PIN Confirmation | C44: TS_AU_004 | D44: Confirm transaction using Face ID / Touch ID | E44: 1. Device supports Face ID / Touch ID 2. Biometric authentication is enabled in MoMo | F44: 1. Complete entering transfer information 2. Tap "Continue" 3. Confirm using Face ID / Touch ID | G44: Face ID / Touch ID: valid | H44: Transaction successfully confirmed via biometrics. | J44: NT | K44: Medium | L44: Medium | M44: Positive
A45: TC_038 | B45: PIN Confirmation | C45: TS_AU_005 | D45: Tap Cancel on the PIN entry screen | E45: 1. Transfer information has been fully entered | F45: 1. On the PIN entry screen 2. Tap the "Cancel" button or back | G45: Action: Cancel confirmation | H45: Transaction is cancelled. Returns to the previous screen. Wallet balance unchanged. | J45: NT | K45: Low | L45: Medium | M45: Negative
A46: TC_039 | B46: PIN Confirmation | C46: TS_AU_006 | D46: Confirmation session times out while entering PIN | E46: 1. Transfer information has been fully entered | F46: 1. Go to the PIN entry screen 2. Leave the screen idle (no action) for the timeout duration | G46: No action for 60–120 seconds | H46: Session expires. Timeout message is displayed. Transaction is not performed. | J46: NT | K46: Medium | L46: Medium | M46: Negative
A47: TC_040 | B47: PIN Confirmation | C47: TS_AU_007 | D47: Face ID/Touch ID fails → is there a fallback to PIN entry? | E47: 1. Device supports Face ID / Touch ID 2. Biometric authentication is enabled in MoMo | F47: 1. On the PIN entry screen. 2. Cover the face; Face ID / Touch ID cannot be recognized 3. Observe the screen | G47: Face ID / Touch ID: invalid | H47: Confirmation fails because Face ID / Touch ID could not be recognized. Falls back to the PIN entry screen to continue. | J47: NT | K47: Medium | L47: Medium | M47: Negative
A48: TC_041 | B48: PIN Confirmation | C48: TS_AU_008 | D48: Face ID/Touch ID fails → is there a fallback to PIN entry? | E48: 1. Device supports Face ID / Touch ID 2. Biometric authentication is enabled in MoMo | F48: 1. On the PIN entry screen 2. Camera cannot recognize the face (low light/wrong angle) 3. Observe the screen | G48: Face ID/Touch ID: invalid | H48: Confirmation fails because Face ID/Touch ID could not be recognized. Falls back to the PIN entry screen to continue. | J48: NT | K48: Medium | L48: Medium | M48: Negative
A49: TC_042 | B49: PIN Confirmation | C49: TS_AU_009 | D49: Change PIN right before confirming the transaction (can the old PIN still be used?) | E49: 1. Transfer information has been fully entered 2. PIN changed before confirming the transaction | F49: 1. Successfully change PIN (simulated as changed on another device) 2. Return to the transaction page 3. Observe the screen | G49: 1. Face ID / Touch ID: invalid 2. Enter the old PIN | H49: Transaction fails. Inline message "Incorrect PIN" is displayed. Screen prompts to re-enter the PIN | J49: NT | K49: High | L49: Medium | M49: Negative
A50: TC_043 | B50: PIN Confirmation | C50: TS_AU_010 | D50: Forget PIN mid-transfer flow → does it lead to the forgot-password flow? | E50: 1. Transfer information has been fully entered | F50: 1. Tap "Forgot PIN?" 2. Observe the screen | G50: 1. Face ID / Touch ID: invalid 2. Tap "Forgot PIN?" | H50: Screen displays a popup "Reset verification PIN" | J50: NT | K50: Medium | L50: Medium | M50: Negative
A51: TC_044 | B51: Transaction Result | C51: TS_RS_001 | D51: Wallet balance decreases correctly after a successful transaction | E51: 1. Wallet balance before the transaction is known | F51: 1. Record the balance before the transaction 2. Successfully perform the transfer 3. Check the balance afterward | G51: Balance before: 500,000đ Transfer amount: 100,000đ | H51: Balance after transaction = 400,000đ (decreased by exactly the transferred amount). | J51: NT | K51: High | L51: High | M51: Positive
A52: TC_045 | B52: Transaction Result | C52: TS_RS_002 | D52: Transaction fails due to loss of network connection | E52: 1. Already on the confirmation screen or processing | F52: 1. Start the transfer 2. Turn off WiFi/4G midway 3. Observe the result | G52: Network connection: OFF midway | H52: Connection error message displayed. Transaction not completed. Wallet balance unchanged (or refunded if already deducted). | J52: NT | K52: High | L52: High | M52: Negative
A53: TC_046 | B53: Transaction Result | C53: TS_RS_003 | D53: Transaction history updates after a successful transfer | E53: 1. Transfer transaction was successful | F53: 1. Perform a successful transaction 2. Go to "Transaction History" 3. Check the transaction just performed | G53: Transaction just transferred: 50,000đ | H53: Transaction appears in the history with full information: amount, recipient, time, status "Successful". | J53: NT | K53: Medium | L53: High | M53: Positive
A54: TC_047 | B54: Transaction Result | C54: TS_RS_004 | D54: Tap "Confirm" twice in quick succession (double-tap) → does it create 2 transactions? | E54: 1. Transfer transaction was successful | F54: 1. Start the transfer 2. Tap the "Confirm" button twice in quick succession (double-tap) 3. Observe the screen | G54: "Amount: 50,000đ Recipient: 0901234567" | H54: The system processes only 1 transaction even if "Confirm" is tapped twice in quick succession (double-tap). The "Confirm" button is disabled/hidden after the first tap, or the server rejects the duplicate request. No duplicate transaction is created; the wallet balance is deducted exactly once (50,000đ). | I54: Sent duplicate POST request (simulating double-tap). API processed only 1 request and returned success with a note preventing duplicate processing — matches expected result. | J54: Pass | K54: Medium | L54: High | M54: Positive | O54: API Simulation (Postman) | P54: SCRUM-5
A55: TC_048 | B55: Transaction Result | C55: TS_RS_005 | D55: Server timeout, unclear whether it succeeded or failed → how does the app display the "processing" state, and does it auto-sync afterward? | E55: 1. Already tapped Confirm transaction 2. Waiting for a response from the server | F55: 1. Simulate a slow server response/timeout right after sending the confirmation request. 2. Observe the screen while waiting. 3. Once the network returns, observe the final state | G55: Network: simulated timeout (delay > X seconds) | H55: App clearly displays "Processing..." and prevents further taps. Once a response arrives or the app is reopened, the system auto-syncs and displays the correct actual status. It does not hang indefinitely. | J55: NT | K55: Medium | L55: High | M55: Positive
A56: TC_049 | B56: Transaction Result | C56: TS_RS_006 | D56: Transaction succeeds but the app crashes right after → does it display correctly in history when reopened? | E56: 1. Transaction has already been successfully processed by the server | F56: 1. Right after the server returns a successful result (before the UI can display it), force-close the app. 2. Reopen the app. 3. Check the transaction history and balance | G56: Action: force-close the app right after the transaction succeeds | H56: On reopening the app, the transaction still displays fully and accurately in the history (since it was saved on the server). Wallet balance updates correctly. No data is lost due to the client-side crash. | J56: NT | K56: Medium | L56: High | M56: Positive
A57: TC_050 | B57: Security | C57: TS_SC_001 | D57: Transfer money when the account has not completed KYC verification | E57: 1. MoMo account has not completed identity verification (KYC) | F57: 1. Log in with a non-KYC account 2. Perform a transfer | G57: Account: non-KYC | H57: A message requesting identity verification is displayed. Transaction is restricted or blocked. | J57: NT | K57: High | L57: High | M57: Security | N57: Needs BA confirmation: does the policy fully block, or only limit the amount?
A58: TC_051 | B58: Security | C58: TS_SC_002 | D58: Transfer money with no network connection | E58: 1. WiFi and mobile data are completely turned off | F58: 1. Turn off network 2. Open MoMo 3. Perform a transfer | G58: Network: OFF | H58: Message "No network connection" is displayed, or the app crashes. Cannot perform the transaction. | J58: NT | K58: High | L58: High | M58: Negative
...

Sheet Test Summary
A1: TEST SUMMARY – Money Transfer Feature | MoMo
A2: Feature | B2: Total TCs | C2: Positive | D2: Negative | E2: Boundary | F2: Security
A3: Phone Number Input | B3: =COUNTIF('Test Cases'!$B$8:$B$66,$A3) -> 12 | C3: =COUNTIFS('Test Cases'!$B$8:$B$66,$A3,'Test Cases'!$M$8:$M$66,C$2) -> 2 | D3: =COUNTIFS('Test Cases'!$B$8:$B$66,$A3,'Test Cases'!$M$8:$M$66,D$2) -> 10 | E3: =COUNTIFS('Test Cases'!$B$8:$B$66,$A3,'Test Cases'!$M$8:$M$66,E$2) -> 0 | F3: =COUNTIFS('Test Cases'!$B$8:$B$66,$A3,'Test Cases'!$M$8:$M$66,F$2) -> 0
A4: Amount Input | B4: =COUNTIF('Test Cases'!$B$8:$B$66,$A4) -> 10 | C4: =COUNTIFS('Test Cases'!$B$8:$B$66,$A4,'Test Cases'!$M$8:$M$66,C$2) -> 1 | D4: =COUNTIFS('Test Cases'!$B$8:$B$66,$A4,'Test Cases'!$M$8:$M$66,D$2) -> 5 | E4: =COUNTIFS('Test Cases'!$B$8:$B$66,$A4,'Test Cases'!$M$8:$M$66,E$2) -> 4 | F4: =COUNTIFS('Test Cases'!$B$8:$B$66,$A4,'Test Cases'!$M$8:$M$66,F$2) -> 0
A5: Account Limit | B5: =COUNTIF('Test Cases'!$B$8:$B$66,$A5) -> 11 | C5: =COUNTIFS('Test Cases'!$B$8:$B$66,$A5,'Test Cases'!$M$8:$M$66,C$2) -> 3 | D5: =COUNTIFS('Test Cases'!$B$8:$B$66,$A5,'Test Cases'!$M$8:$M$66,D$2) -> 4 | E5: =COUNTIFS('Test Cases'!$B$8:$B$66,$A5,'Test Cases'!$M$8:$M$66,E$2) -> 4 | F5: =COUNTIFS('Test Cases'!$B$8:$B$66,$A5,'Test Cases'!$M$8:$M$66,F$2) -> 0
A6: PIN Confirmation | B6: =COUNTIF('Test Cases'!$B$8:$B$66,$A6) -> 10 | C6: =COUNTIFS('Test Cases'!$B$8:$B$66,$A6,'Test Cases'!$M$8:$M$66,C$2) -> 2 | D6: =COUNTIFS('Test Cases'!$B$8:$B$66,$A6,'Test Cases'!$M$8:$M$66,D$2) -> 7 | E6: =COUNTIFS('Test Cases'!$B$8:$B$66,$A6,'Test Cases'!$M$8:$M$66,E$2) -> 0 | F6: =COUNTIFS('Test Cases'!$B$8:$B$66,$A6,'Test Cases'!$M$8:$M$66,F$2) -> 1
A7: Transaction Result | B7: =COUNTIF('Test Cases'!$B$8:$B$66,$A7) -> 6 | C7: =COUNTIFS('Test Cases'!$B$8:$B$66,$A7,'Test Cases'!$M$8:$M$66,C$2) -> 5 | D7: =COUNTIFS('Test Cases'!$B$8:$B$66,$A7,'Test Cases'!$M$8:$M$66,D$2) -> 1 | E7: =COUNTIFS('Test Cases'!$B$8:$B$66,$A7,'Test Cases'!$M$8:$M$66,E$2) -> 0 | F7: =COUNTIFS('Test Cases'!$B$8:$B$66,$A7,'Test Cases'!$M$8:$M$66,F$2) -> 0
A8: Security | B8: =COUNTIF('Test Cases'!$B$8:$B$66,$A8) -> 7 | C8: =COUNTIFS('Test Cases'!$B$8:$B$66,$A8,'Test Cases'!$M$8:$M$66,C$2) -> 0 | D8: =COUNTIFS('Test Cases'!$B$8:$B$66,$A8,'Test Cases'!$M$8:$M$66,D$2) -> 2 | E8: =COUNTIFS('Test Cases'!$B$8:$B$66,$A8,'Test Cases'!$M$8:$M$66,E$2) -> 1 | F8: =COUNTIFS('Test Cases'!$B$8:$B$66,$A8,'Test Cases'!$M$8:$M$66,F$2) -> 4
A9: Message | B9: =COUNTIF('Test Cases'!$B$8:$B$66,$A9) -> 3 | C9: =COUNTIFS('Test Cases'!$B$8:$B$66,$A9,'Test Cases'!$M$8:$M$66,C$2) -> 2 | D9: =COUNTIFS('Test Cases'!$B$8:$B$66,$A9,'Test Cases'!$M$8:$M$66,D$2) -> 0 | E9: =COUNTIFS('Test Cases'!$B$8:$B$66,$A9,'Test Cases'!$M$8:$M$66,E$2) -> 0 | F9: =COUNTIFS('Test Cases'!$B$8:$B$66,$A9,'Test Cases'!$M$8:$M$66,F$2) -> 1
A10: TOTAL | B10: =SUM(B3:B9) -> 59 | C10: =SUM(C3:C9) -> 15 | D10: =SUM(D3:D9) -> 29 | E10: =SUM(E3:E9) -> 9 | F10: =SUM(F3:F9) -> 6
A12: STATUS LEGEND
A13: Pass | B13: Fail | C13: NT (Not Tested) | D13: N/A
A14: 2 | B14: 0 | C14: 57 | D14: 0
A22: STATUS BREAKDOWN (from Status column)
A23: Status | B23: Count
A24: Pass | B24: =COUNTIF('Test Cases'!$J$8:$J$66,A24) -> 2
A25: Fail | B25: =COUNTIF('Test Cases'!$J$8:$J$66,A25) -> 0
A26: NT | B26: =COUNTIF('Test Cases'!$J$8:$J$66,A26) -> 57
A27: N/A | B27: =COUNTIF('Test Cases'!$J$8:$J$66,A27) -> 0
